Workbook

Sheet Data_Input
C2: Assumption | D2: 800000000 | E2: 0.5 | F2: =D2*E2 -> 400000000 | G2: =F2/12 -> 33333333
C3: A) Cullet (K.8) | L3: Cullet (K.8) | S3: 12
C4: Targeted cullet supply : BGC cullet ratio target @80% in 3years ref. 2022 sustainability report ; growth 3-4% CAGR | P4: Inflation | Q4: 0.05
C5: Yr | D5: 2025F | E5: 2026F | F5: 2027F | G5: 2028F | H5: 2029F | L5: Inflation | M5: 0.05 | N5: 1.05 | P5: YR | Q5: 2023 | R5: 2024F | S5: 2025F | T5: 2026F | U5: 2027F | V5: 2028F | Y5: WC | Z5: 2024F | AA5: 2025F | AB5: 2026F | AC5: 2027F | AD5: 2028F
C6: Qty.Kg (monthly) | D6: 8000000 | E6: 10000000 | F6: 12000000 | G6: 12000000 | H6: 12000000 | L6: Raw cullet | M6: 2.3 | N6: Thb/Kg | P6: FC (Thb)Treat | Q6: 800000 | R6: =Q6*$N$5 -> 840000 | S6: =R6*$N$5 -> 882000 | T6: =S6*$N$5 -> 926100 | U6: =T6*$N$5 -> 972405 | V6: =U6*$N$5 -> 1021025.2 | X6: 30 | Y6: Stock | Z6: =(D7*D8)/12 -> 18400000 | AA6: =(E7*E8)/12 -> 24150000 | AB6: =(F7*F8)/12 -> 30429000 | AC6: =(G7*G8)/12 -> 31950450 | AD6: =(H7*H8)/12 -> 33547972
C7: Qty.kg (annual) | D7: =D6*12 -> 96000000 | E7: =E6*12 -> 120000000 | F7: =F6*12 -> 144000000 | G7: =G6*12 -> 144000000 | H7: =H6*12 -> 144000000 | L7: Treatment | M7: 0.5 | N7: Thb/Kg | P7: Depre treat | Q7: 470000 | R7: =Q7*$N$5+R18 -> 410166.67 | S7: =R7*$N$5 -> 430675 | T7: =S7*$N$5 -> 452208.75 | U7: =T7*$N$5 -> 474819.19 | V7: =U7*$N$5 -> 498560.15 | X7: 20 | Y7: AR | Z7: =(Z6/30)*20 -> 12266667 | AA7: =(AA6/30)*20 -> 16100000 | AB7: =(AB6/30)*20 -> 20286000 | AC7: =(AC6/30)*20 -> 21300300 | AD7: =(AD6/30)*20 -> 22365315
C8: Raw mat | D8: =$M$6 -> 2.3 | E8: =D8*$N$5 -> 2.415 | F8: =E8*$N$5 -> 2.53575 | G8: =F8*$N$5 -> 2.6625375 | H8: =G8*$N$5 -> 2.7956644 | L8: Avg.Logistic | M8: 0.1 | N8: Thb/Kg | P8: VC (Thb/kg\)Treat | Q8: 0.05 | R8: =Q8*$N$5 -> 0.0525 | S8: =R8*$N$5 -> 0.055125 | T8: =S8*$N$5 -> 0.05788125 | U8: =T8*$N$5 -> 0.060775312 | V8: =U8*$N$5 -> 0.063814078 | X8: 5 | Y8: AP | Z8: =(Z6/30)*5 -> 3066666.7 | AA8: =(AA6/30)*5 -> 4025000 | AB8: =(AB6/30)*5 -> 5071500 | AC8: =(AC6/30)*5 -> 5325075 | AD8: =(AD6/30)*5 -> 5591328.8
C9: Treatment | D9: =$M$7 -> 0.5 | E9: =D9*$N$5 -> 0.525 | F9: =E9*$N$5 -> 0.55125 | G9: =F9*$N$5 -> 0.5788125 | H9: =G9*$N$5 -> 0.60775313 | L9: QTY.base | M9: 1000 | N9: Ton> kg | P9: Yield Loss (%) | Q9: 0.012 | R9: 0.012 | S9: 0.012 | T9: 0.012 | U9: 0.012 | V9: 0.012 | Y9: WC Need | Z9: =Z6+Z7-Z8 -> 27600000 | AA9: =AA6+AA7-AA8 -> 36225000 | AB9: =AB6+AB7-AB8 -> 45643500 | AC9: =AC6+AC7-AC8 -> 47925675 | AD9: =AD6+AD7-AD8 -> 50321959
C10: Sell(Ex-work) | D10: =D8+D9 -> 2.8 | E10: =E8+E9 -> 2.94 | F10: =F8+F9 -> 3.087 | G10: =G8+G9 -> 3.24135 | H10: =H8+H9 -> 3.4034175 | L10: EPR | M10: 0.1 | N10: Thb/Kg | P10: Yield Loss (kg) | R10: =D6*R9 -> 96000 | S10: =E6*S9 -> 120000 | T10: =F6*T9 -> 144000 | U10: =G6*U9 -> 144000 | V10: =H6*V9 -> 144000
C11: Logistic | D11: =$M$8 -> 0.1 | E11: =D11*$N$5 -> 0.105 | F11: =E11*$N$5 -> 0.11025 | G11: =F11*$N$5 -> 0.1157625 | H11: =G11*$N$5 -> 0.12155062 | P11: Yield Loss amt.(Thb) | R11: =R10*D8 -> 220800 | S11: =S10*E8 -> 289800 | T11: =T10*F8 -> 365148 | U11: =U10*G8 -> 383405.4 | V11: =V10*H8 -> 402575.67 | Y11: Interest amt. | Z11: =Z9*$Z$15 -> 1380000 | AA11: =AA9*$Z$15 -> 1811250 | AB11: =AB9*$Z$15 -> 2282175 | AC11: =AC9*$Z$15 -> 2396283.8 | AD11: =AD9*$Z$15 -> 2516097.9
C12: Avg.Net price | D12: =D10+D11 -> 2.9 | E12: =E10+E11 -> 3.045 | F12: =F10+F11 -> 3.19725 | G12: =G10+G11 -> 3.3571125 | H12: =H10+H11 -> 3.5249681 | P12: Yield Loss (Thb/kg) | Q12: 0.04 | R12: =R11/D6 -> 0.0276 | S12: =S11/E6 -> 0.02898 | T12: =T11/F6 -> 0.030429 | U12: =U11/G6 -> 0.03195045 | V12: =V11/H6 -> 0.033547973
P13: FC (Thb) SG&A | Q13: 1610000 | R13: =Q13*$N$5 -> 1690500 | S13: =R13*$N$5 -> 1775025 | T13: =S13*$N$5 -> 1863776.2 | U13: =T13*$N$5 -> 1956965.1 | V13: =U13*$N$5 -> 2054813.3 | Y13: 12 | Z13: =Z11/$Y$13 -> 115000 | AA13: =AA11/$Y$13 -> 150937.5 | AB13: =AB11/$Y$13 -> 190181.25 | AC13: =AC11/$Y$13 -> 199690.31 | AD13: =AD11/$Y$13 -> 209674.83
C14: Vol.Growth | E14: =(E6/D6)-1 -> 0.25 | F14: =(F6/E6)-1 -> 0.2 | G14: =(G6/F6)-1 -> 0 | H14: =(H6/G6)-1 -> 0 | P14: Depre SG&A | Q14: 87000 | R14: =Q14*$N$5 -> 91350 | S14: =R14*$N$5 -> 95917.5 | T14: =S14*$N$5 -> 100713.38 | U14: =T14*$N$5 -> 105749.04 | V14: =U14*$N$5 -> 111036.5
C15: Value Growth | E15: =((E7*E8)/(D7*D8))-1 -> 0.3125 | F15: =((F7*F8)/(E7*E8))-1 -> 0.26 | G15: =((G7*G8)/(F7*F8))-1 -> 0.05 | H15: =((H7*H8)/(G7*G8))-1 -> 0.05 | P15: VC (Thb/kg\)SG&A | R15: =Q15*$N$5 -> 0 | S15: =R15*$N$5 -> 0 | T15: =S15*$N$5 -> 0 | U15: =T15*$N$5 -> 0 | V15: =U15*$N$5 -> 0 | Y15: Int.rate | Z15: 0.05
E16: =E12/D12-1 -> 0.05 | F16: =F12/E12-1 -> 0.05 | G16: =G12/F12-1 -> 0.05 | H16: =H12/G12-1 -> 0.05 | P16: Financing | Q16: 310000 | R16: 315000 | S16: 315000 | T16: 315000 | U16: 315000 | V16: 315000 | Y16: WC Day | Z16: =30+20-5 -> 45
C17: A1.1) By Product | L17: By Product | P17: Capex | R17: -10000000 | S17: -10000000 | T17: -10000000 | U17: -10000000 | V17: -10000000 | W17: =SUM(R17:V17) -> -50000000
C18: Yr | D18: 2025F | E18: 2026F | F18: 2027F | G18: 2028F | H18: 2029F | L18: Inflation | M18: 0.05 | N18: 1.05 | P18: Depre (Capex) | R18: =R17/120 -> -83333.333 | S18: =S17/120 -> -83333.333 | T18: =T17/120 -> -83333.333 | U18: =U17/120 -> -83333.333 | V18: =V17/120 -> -83333.333
C19: Qty.Kg (monthly) | D19: =D6*$M$20 -> 32000 | E19: =E6*$M$20 -> 40000 | F19: =F6*$M$20 -> 48000 | G19: =G6*$M$20 -> 48000 | H19: =H6*$M$20 -> 48000 | L19: Avg. Sell | M19: 18 | N19: Thb/Kg | P19: Depre (Capex) Year | Q19: 10 | R19: =R18*S3 -> -1000000
C20: Qty.kg (annual) | D20: =D19*12 -> 384000 | E20: =E19*12 -> 480000 | F20: =F19*12 -> 576000 | G20: =G19*12 -> 576000 | H20: =H19*12 -> 576000 | L20: By product | M20: 0.004 | N20: Kg
L21: EPR | M21: 0.1 | N21: Thb/Kg
P22: *** Financing cost supposed to be better rate than current rate , as BSR intend to move from SME to Coperate port
C24: B) Cullet (Sri racha) | L24: Cullet (Sri racha)
C26: Yr | D26: 2025F | E26: 2026F | F26: 2027F | G26: 2028F | H26: 2029F | L26: Inflation | M26: 0.05 | N26: =$N$5 -> 1.05
C27: Qty.Kg (monthly) | D27: =3500*1000 -> 3500000 | E27: =4000*1000 -> 4000000 | F27: =4500*1000 -> 4500000 | G27: =5000*1000 -> 5000000 | H27: =6000*1000 -> 6000000 | L27: Net price | M27: =D12 -> 2.9 | N27: Thb/Kg
C28: Qty.kg (annual) | D28: =D27*12 -> 42000000 | E28: =E27*12 -> 48000000 | F28: =F27*12 -> 54000000 | G28: =G27*12 -> 60000000 | H28: =H27*12 -> 72000000 | L28: Treatment | M28: 0 | N28: Thb/Kg
C29: Raw | D29: =D31-$M$30 -> 2.69 | E29: =E31-$M$30 -> 2.825 | F29: =F31-$M$30 -> 2.96675 | G29: =G31-$M$30 -> 3.1155875 | H29: =H31-$M$30 -> 3.2718669 | L29: QTY.base | M29: 1000 | N29: Ton> kg
C30: Gap from Center | D30: 0.2 | E30: 0.2 | F30: 0.2 | G30: 0.2 | H30: 0.2 | L30: Com.Base | M30: 0.01 | N30: Thb/Kg
C31: Avg.Net price | D31: =$M$27-D30 -> 2.7 | E31: =D31*$N$26 -> 2.835 | F31: =E31*$N$26 -> 2.97675 | G31: =F31*$N$26 -> 3.1255875 | H31: =G31*$N$26 -> 3.2818669 | L31: EPR | M31: 0.1 | N31: Thb/Kg
C34: C) Float glass (Sri racha) | L34: Float glass (Sri racha)
C36: Yr | D36: 2025F | E36: 2026F | F36: 2027F | G36: 2028F | H36: 2029F | L36: Inflation | M36: 0.05 | N36: =$N$5 -> 1.05
C37: Qty.Kg (monthly) | D37: =1000*1000 -> 1000000 | E37: =1200*1000 -> 1200000 | F37: =1500*1000 -> 1500000 | G37: =1700*1000 -> 1700000 | H37: =2000*1000 -> 2000000 | L37: Net price | M37: =4.05 -> 4.05 | N37: Thb/Kg
C38: Qty.kg (annual) | D38: =D37*12 -> 12000000 | E38: =E37*12 -> 14400000 | F38: =F37*12 -> 18000000 | G38: =G37*12 -> 20400000 | H38: =H37*12 -> 24000000 | L38: Treatment | M38: 0 | N38: Thb/Kg
C39: Raw | D39: =D40-$M$40 -> 4.04 | E39: =E40-$M$40 -> 4.2425 | F39: =F40-$M$40 -> 4.455125 | G39: =G40-$M$40 -> 4.6783813 | H39: =H40-$M$40 -> 4.9128003 | L39: QTY.base | M39: 1000 | N39: Ton> kg
C40: Avg.Net price | D40: =$M$37 -> 4.05 | E40: =D40*$N$36 -> 4.2525 | F40: =E40*$N$36 -> 4.465125 | G40: =F40*$N$36 -> 4.6883812 | H40: =G40*$N$36 -> 4.9228003 | L40: Com.Base | M40: 0.01 | N40: Thb/Kg
L41: EPR | M41: 0 | N41: Thb/Kg
C43: D) Tempered glass (Sri racha) | L43: Tempered glass (Sri racha)
C45: Yr | D45: 2025F | E45: 2026F | F45: 2027F | G45: 2028F | H45: 2029F | L45: Inflation | M45: 0.05 | N45: =$N$5 -> 1.05
C46: Qty.Kg (monthly) | L46: Net price | M46: 3.5 | N46: Thb/Kg
C47: Qty.kg (annual) | D47: =D46*12 -> 0 | E47: =E46*12 -> 0 | F47: =F46*12 -> 0 | G47: =G46*12 -> 0 | H47: =H46*12 -> 0 | L47: Treatment | M47: 0 | N47: Thb/Kg
C48: Raw | D48: =D49-$M$49 -> 3.49 | E48: =E49-$M$49 -> 3.665 | F48: =F49-$M$49 -> 3.84875 | G48: =G49-$M$49 -> 4.0416875 | H48: =H49-$M$49 -> 4.2442719 | L48: QTY.base | M48: 1000 | N48: Ton> kg
...

Sheet Scenario
A1: 0.79166667
B2: Sensitivity Factor
B3: 1) Cullet K.8 Vol . + By product
B5: Best case scenario | I5: Base case scenario | P5: Worst case scenario
B7: Cullet Vol. | E7: EPR | I7: Cullet Vol. | L7: EPR | P7: Cullet Vol. | S7: EPR
B8: Yr | C8: 2025F | D8: 2026F | E8: 2027F | F8: 2028F | G8: 2029F | I8: Yr | J8: 2025F | K8: 2026F | L8: 2027F | M8: 2028F | N8: 2029F | P8: Yr | Q8: 2025F | R8: 2026F | S8: 2027F | T8: 2028F | U8: 2029F
B9: Qty.Kg (monthly) | C9: 9000000 | D9: 10000000 | E9: 13000000 | F9: 14000000 | G9: 15000000 | I9: Qty.Kg (monthly) | J9: 9000000 | K9: 9000000 | L9: 12000000 | M9: 14000000 | N9: 15000000 | P9: Qty.Kg (monthly) | Q9: 8000000 | R9: 9000000 | S9: 10000000 | T9: 11000000 | U9: 12000000
B10: Qty.kg (annual) | C10: =C9*12 -> 108000000 | D10: =D9*12 -> 120000000 | E10: =E9*12 -> 156000000 | F10: =F9*12 -> 168000000 | G10: =G9*12 -> 180000000 | I10: Qty.kg (annual) | J10: =J9*12 -> 108000000 | K10: =K9*12 -> 108000000 | L10: =L9*12 -> 144000000 | M10: =M9*12 -> 168000000 | N10: =N9*12 -> 180000000 | P10: Qty.kg (annual) | Q10: =Q9*12 -> 96000000 | R10: =R9*12 -> 108000000 | S10: =S9*12 -> 120000000 | T10: =T9*12 -> 132000000 | U10: =U9*12 -> 144000000
B11: Raw mat | C11: 2.3 | D11: 2.415 | E11: 2.53575 | F11: 2.6625375 | G11: 2.7956644 | I11: Raw mat | J11: 2.3 | K11: 2.415 | L11: 2.53575 | M11: 2.6625375 | N11: 2.7956644 | P11: Raw mat | Q11: 2.3 | R11: 2.415 | S11: 2.53575 | T11: 2.6625375 | U11: 2.7956644
B12: Treatment | C12: 0.5 | D12: 0.525 | E12: 0.55125 | F12: 0.5788125 | G12: 0.60775313 | I12: Treatment | J12: 0.5 | K12: 0.525 | L12: 0.55125 | M12: 0.5788125 | N12: 0.60775313 | P12: Treatment | Q12: 0.5 | R12: 0.525 | S12: 0.55125 | T12: 0.5788125 | U12: 0.60775313
B13: Sell(Ex-work) | C13: 2.8 | D13: 2.94 | E13: 3.087 | F13: 3.24135 | G13: 3.4034175 | I13: Sell(Ex-work) | J13: 2.8 | K13: 2.94 | L13: 3.087 | M13: 3.24135 | N13: 3.4034175 | P13: Sell(Ex-work) | Q13: 2.8 | R13: 2.94 | S13: 3.087 | T13: 3.24135 | U13: 3.4034175
B14: Logistic | C14: 0.1 | D14: 0.105 | E14: 0.11025 | F14: 0.1157625 | G14: 0.12155063 | I14: Logistic | J14: 0.1 | K14: 0.105 | L14: 0.11025 | M14: 0.1157625 | N14: 0.12155063 | P14: Logistic | Q14: 0.1 | R14: 0.105 | S14: 0.11025 | T14: 0.1157625 | U14: 0.12155063
B15: Avg.Net price | C15: 2.9 | D15: 3.045 | E15: 3.19725 | F15: 3.3571125 | G15: 3.5249681 | I15: Avg.Net price | J15: 2.9 | K15: 3.045 | L15: 3.19725 | M15: 3.3571125 | N15: 3.5249681 | P15: Avg.Net price | Q15: 2.9 | R15: 3.045 | S15: 3.19725 | T15: 3.3571125 | U15: 3.5249681
B17: 0.004 | I17: 0.004 | P17: 0.004
B18: By Product | C18: คิดเป็น 0.4% ของ cullet k.8 | I18: By Product | J18: คิดเป็น 0.4% ของ cullet k.8 | P18: By Product | Q18: คิดเป็น 0.4% ของ cullet k.8
B19: Yr | C19: 2025F | D19: 2026F | E19: 2027F | F19: 2028F | G19: 2029F | I19: Yr | J19: 2025F | K19: 2026F | L19: 2027F | M19: 2028F | N19: 2029F | P19: Yr | Q19: 2025F | R19: 2026F | S19: 2027F | T19: 2028F | U19: 2029F
B20: Qty.Kg (monthly) | C20: =$B$17*C9 -> 36000 | D20: =$B$17*D9 -> 40000 | E20: =$B$17*E9 -> 52000 | F20: =$B$17*F9 -> 56000 | G20: =$B$17*G9 -> 60000 | I20: Qty.Kg (monthly) | J20: =$I$17*J9 -> 36000 | K20: =$I$17*K9 -> 36000 | L20: =$I$17*L9 -> 48000 | M20: =$I$17*M9 -> 56000 | N20: =$I$17*N9 -> 60000 | P20: Qty.Kg (monthly) | Q20: =$I$17*Q9 -> 32000 | R20: =$I$17*R9 -> 36000 | S20: =$I$17*S9 -> 40000 | T20: =$I$17*T9 -> 44000 | U20: =$I$17*U9 -> 48000
B21: Qty.kg (annual) | C21: =C20*12 -> 432000 | D21: =D20*12 -> 480000 | E21: =E20*12 -> 624000 | F21: =F20*12 -> 672000 | G21: =G20*12 -> 720000 | I21: Qty.kg (annual) | J21: =J20*12 -> 432000 | K21: =K20*12 -> 432000 | L21: =L20*12 -> 576000 | M21: =M20*12 -> 672000 | N21: =N20*12 -> 720000 | P21: Qty.kg (annual) | Q21: =Q20*12 -> 384000 | R21: =R20*12 -> 432000 | S21: =S20*12 -> 480000 | T21: =T20*12 -> 528000 | U21: =U20*12 -> 576000
B22: Net Price | C22: =Data_Input!$M$19 -> 18 | D22: =Data_Input!$M$19 -> 18 | E22: =Data_Input!$M$19 -> 18 | F22: =Data_Input!$M$19 -> 18 | G22: =Data_Input!$M$19 -> 18 | J22: =Data_Input!$M$19 -> 18 | K22: =Data_Input!$M$19 -> 18 | L22: =Data_Input!$M$19 -> 18 | M22: =Data_Input!$M$19 -> 18 | N22: =Data_Input!$M$19 -> 18 | Q22: =Data_Input!$M$19 -> 18 | R22: =Data_Input!$M$19 -> 18 | S22: =Data_Input!$M$19 -> 18 | T22: =Data_Input!$M$19 -> 18 | U22: =Data_Input!$M$19 -> 18
B24: 2) Subsidy
B26: Best case scenario | I26: Base case scenario | P26: Worst case scenario
B27: Product | C27: 2025F | D27: 2026F | E27: 2027F | F27: 2028F | G27: 2029F | I27: Product | J27: 2025F | K27: 2026F | L27: 2027F | M27: 2028F | N27: 2029F | P27: Product | Q27: 2025F | R27: 2026F | S27: 2027F | T27: 2028F | U27: 2029F
B28: Cullet | E28: 0.2 | F28: 0.2 | G28: 0.2 | I28: Cullet | L28: 0.1 | M28: 0.1 | N28: 0.1 | P28: Cullet | S28: 0.05 | T28: 0.05 | U28: 0.05
B29: PET | E29: 1.15 | F29: 1.15 | G29: 1.15 | I29: PET | L29: 0.75 | M29: 0.75 | N29: 0.75 | P29: PET | S29: 0.5 | T29: 0.5 | U29: 0.5
B30: CAN | E30: 2 | F30: 2 | G30: 2 | I30: CAN | L30: 1 | M30: 1 | N30: 1 | P30: CAN | S30: 0.75 | T30: 0.75 | U30: 0.75
B35: 3) Discount Rate
B37: 0.09
B38: 0.1
B39: 0.12
B42: 4) WC need
C46: sensitivity Model
E48: Cullte Oty.
B52: Best Case Revenue
B53: Base Case Revenue
B54: Worst Case Revenue

Sheet Assumption_sheet
A1: Best | H1: ตารางสมมติฐาน
H2: งบการเงิน
A3: Financial Projection BS Glass Recycling Company Limited | F3: =F4+543 -> 2565 | G3: =G4+543 -> 2566 | H3: =H4+543 -> 2567 | I3: =I4+543 -> 2568 | J3: =J4+543 -> 2569 | K3: =K4+543 -> 2570 | L3: =L4+543 -> 2571 | M3: =M4+543 -> 2572
A4: year | F4: =YEAR(F6) -> 2022 | G4: =YEAR(G6) -> 2023 | H4: =YEAR(H6) -> 2024 | I4: =YEAR(I6) -> 2025 | J4: =YEAR(J6) -> 2026 | K4: =YEAR(K6) -> 2027 | L4: =YEAR(L6) -> 2028 | M4: =YEAR(M6) -> 2029
A5: Unit : THB. | D5: Unit | E5: Constant | F5: 0 | G5: 0 | H5: 0 | I5: =H5+1 -> 1 | J5: =I5+1 -> 2 | K5: =J5+1 -> 3 | L5: =K5+1 -> 4 | M5: =L5+1 -> 5
C6: peroid start | F6: 44562 | G6: =F7+1 -> 44927 | H6: =G7+1 -> 45292 | I6: =H7+1 -> 45658 | J6: =I7+1 -> 46023 | K6: =J7+1 -> 46388 | L6: =K7+1 -> 46753 | M6: =L7+1 -> 47119
C7: peroid end. | F7: =eomonth(F6,11) -> 44926 | G7: =eomonth(G6,11) -> 45291 | H7: =eomonth(H6,11) -> 45657 | I7: =eomonth(I6,11) -> 46022 | J7: =eomonth(J6,11) -> 46387 | K7: =eomonth(K6,11) -> 46752 | L7: =eomonth(L6,11) -> 47118 | M7: =eomonth(M6,11) -> 47483
A8: Assumption
C9: Inflation Rate | D9: % | E9: 0.05 | G9: =$E9 -> 0.05 | H9: =$E9 -> 0.05 | I9: =$E9 -> 0.05 | J9: =$E9 -> 0.05 | K9: =$E9 -> 0.05 | L9: =$E9 -> 0.05 | M9: =$E9 -> 0.05
C10: Growth Rate | D10: % | E10: 0.05 | I10: =$E10 -> 0.05 | J10: =$E10 -> 0.05 | K10: =$E10 -> 0.05 | L10: =$E10 -> 0.05 | M10: =$E10 -> 0.05
A11: (Revenue Assumtion)
B12: A) Cullet (K.8)
C13: Product sell revenue | D13: THB | G13: 84804224 | I13: =if($A$1="Base",Scenario!J10*Scenario!J15,if($A$1="Best",Scenario!C10*Scenario!C15,if($A$1="Worst",Scenario!Q10*Scenario!Q15))) -> 313200000 | J13: =if($A$1="Base",Scenario!K10*Scenario!K15,if($A$1="Best",Scenario!D10*Scenario!D15,if($A$1="Worst",Scenario!R10*Scenario!R15))) -> 365400000 | K13: =if($A$1="Base",Scenario!L10*Scenario!L15,if($A$1="Best",Scenario!E10*Scenario!E15,if($A$1="Worst",Scenario!S10*Scenario!S15))) -> 498771000 | L13: =if($A$1="Base",Scenario!M10*Scenario!M15,if($A$1="Best",Scenario!F10*Scenario!F15,if($A$1="Worst",Scenario!T10*Scenario!T15))) -> 563994900 | M13: =if($A$1="Base",Scenario!N10*Scenario!N15,if($A$1="Best",Scenario!G10*Scenario!G15,if($A$1="Worst",Scenario!U10*Scenario!U15))) -> 6.3449426e+08
C14: EPR revenue | D14: THB/Kg. | E14: =if($A$1="Best",Scenario!E$28,if($A$1="Base",Scenario!L$28,if(A1="Worst",Scenario!S$28))) -> 0.2 | G14: 0 | I14: =if($A$1="Base",$E14*Scenario!J10,if($A$1="Best",$E14*Scenario!C10,if($A$1="Worst",$E14*Scenario!Q10))) -> 21600000 | J14: =if($A$1="Base",$E14*Scenario!K10,if($A$1="Best",$E14*Scenario!D10,if($A$1="Worst",$E14*Scenario!R10))) -> 24000000 | K14: =if($A$1="Base",$E14*Scenario!L10,if($A$1="Best",$E14*Scenario!E10,if($A$1="Worst",$E14*Scenario!S10))) -> 31200000 | L14: =if($A$1="Base",$E14*Scenario!M10,if($A$1="Best",$E14*Scenario!F10,if($A$1="Worst",$E14*Scenario!T10))) -> 33600000 | M14: =if($A$1="Base",$E14*Scenario!N10,if($A$1="Best",$E14*Scenario!G10,if($A$1="Worst",$E14*Scenario!U10))) -> 36000000
C15: Total Revenue (By Item) | D15: THB | F15: =sum(F13) -> 0 | G15: =sum(G13:G14) -> 84804224 | I15: =sum(I13:I14) -> 334800000 | J15: =sum(J13:J14) -> 389400000 | K15: =sum(K13:K14) -> 529971000 | L15: =sum(L13:L14) -> 597594900 | M15: =sum(M13:M14) -> 6.7049426e+08
C16: Growth Rate (By Item) | D16: % | J16: =if(J15<>0,J15/I15-1,0) -> 0.16308244 | K16: =if(K15<>0,K15/J15-1,0) -> 0.36099384 | L16: =if(L15<>0,L15/K15-1,0) -> 0.12759925 | M16: =if(M15<>0,M15/L15-1,0) -> 0.12198793
B18: A.1) By Product
C19: Product sell revenue | D19: THB | I19: =if($A$1="Base",Scenario!J21*Scenario!J22,if($A1="Best",Scenario!C21*Scenario!C22,if($A$1="Worst",Scenario!Q21*Scenario!Q22))) -> 7776000 | J19: =if($A$1="Base",Scenario!K21*Scenario!K22,if($A1="Best",Scenario!D21*Scenario!D22,if($A$1="Worst",Scenario!R21*Scenario!R22))) -> 8640000 | K19: =if($A$1="Base",Scenario!L21*Scenario!L22,if($A1="Best",Scenario!E21*Scenario!E22,if($A$1="Worst",Scenario!S21*Scenario!S22))) -> 11232000 | L19: =if($A$1="Base",Scenario!M21*Scenario!M22,if($A1="Best",Scenario!F21*Scenario!F22,if($A$1="Worst",Scenario!T21*Scenario!T22))) -> 12096000 | M19: =if($A$1="Base",Scenario!N21*Scenario!N22,if($A1="Best",Scenario!G21*Scenario!G22,if($A$1="Worst",Scenario!U21*Scenario!U22))) -> 12960000
C20: EPR revenue | D20: THB | E20: =if($A$1="Best",Scenario!E$28,if($A$1="Base",Scenario!L$28,if($A$1="Worst",Scenario!S$28))) -> 0.2 | I20: =if($A$1="Base",$E$20*Scenario!J21,if($A$1="Best",$E$20*Scenario!C21,if($A$1="Worst",$E$20*Scenario!Q21))) -> 86400 | J20: =if($A$1="Base",$E$20*Scenario!K21,if($A$1="Best",$E$20*Scenario!D21,if($A$1="Worst",$E$20*Scenario!R21))) -> 96000 | K20: =if($A$1="Base",$E$20*Scenario!L21,if($A$1="Best",$E$20*Scenario!E21,if($A$1="Worst",$E$20*Scenario!S21))) -> 124800 | L20: =if($A$1="Base",$E$20*Scenario!M21,if($A$1="Best",$E$20*Scenario!F21,if($A$1="Worst",$E$20*Scenario!T21))) -> 134400 | M20: =if($A$1="Base",$E$20*Scenario!N21,if($A$1="Best",$E$20*Scenario!G21,if($A$1="Worst",$E$20*Scenario!U21))) -> 144000
C21: Total Revenue (By Item) | D21: THB | I21: =sum(I19:I20) -> 7862400 | J21: =sum(J19:J20) -> 8736000 | K21: =sum(K19:K20) -> 11356800 | L21: =sum(L19:L20) -> 12230400 | M21: =sum(M19:M20) -> 13104000
C22: Growth Rate (By Item) | D22: % | J22: =if(J21<>0,J21/I21-1,0) -> 0.11111111 | K22: =if(K21<>0,K21/J21-1,0) -> 0.3 | L22: =if(L21<>0,L21/K21-1,0) -> 0.076923077 | M22: =if(M21<>0,M21/L21-1,0) -> 0.071428571
B24: B) Cullet (Sriracha)
C25: Product sell revenue | D25: THB | I25: =Data_Input!D28*Data_Input!$M$27 -> 121800000 | J25: =Data_Input!E28*Data_Input!$M$27 -> 139200000 | K25: =Data_Input!F28*Data_Input!$M$27 -> 156600000 | L25: =Data_Input!G28*Data_Input!$M$27 -> 174000000 | M25: =Data_Input!H28*Data_Input!$M$27 -> 208800000
C26: EPR revenue | D26: THB | E26: =if($A$1="Best",Scenario!E$28,if($A$1="Base",Scenario!L$28,if($A$1="Worst",Scenario!S$28))) -> 0.2 | I26: =$E$26*Data_Input!D28 -> 8400000 | J26: =$E$26*Data_Input!E28 -> 9600000 | K26: =$E$26*Data_Input!F28 -> 10800000 | L26: =$E$26*Data_Input!G28 -> 12000000 | M26: =$E$26*Data_Input!H28 -> 14400000
C27: Total Revenue (By Item) | D27: THB | I27: =sum(I25:I26) -> 130200000 | J27: =sum(J25:J26) -> 148800000 | K27: =sum(K25:K26) -> 167400000 | L27: =sum(L25:L26) -> 186000000 | M27: =sum(M25:M26) -> 223200000
C28: Growth Rate (By Item) | D28: % | J28: =if(J27<>0,J27/I27-1,0) -> 0.14285714 | K28: =if(K27<>0,K27/J27-1,0) -> 0.125 | L28: =if(L27<>0,L27/K27-1,0) -> 0.11111111 | M28: =if(M27<>0,M27/L27-1,0) -> 0.2
B30: C) Float glass (Sri racha)
C31: Product sell revenue | D31: THB | I31: =Data_Input!D40*Data_Input!D38 -> 48600000 | J31: =Data_Input!E40*Data_Input!E38 -> 61236000 | K31: =Data_Input!F40*Data_Input!F38 -> 80372250 | L31: =Data_Input!G40*Data_Input!G38 -> 95642978 | M31: =Data_Input!H40*Data_Input!H38 -> 1.1814721e+08
C32: EPR revenue | D32: THB | E32: =Data_Input!$M$41 -> 0 | I32: =$E$32 -> 0 | J32: =$E$32 -> 0 | K32: =$E$32 -> 0 | L32: =$E$32 -> 0 | M32: =$E$32 -> 0
C33: Total Revenue (By Item) | D33: THB | I33: =sum(I31:I32) -> 48600000 | J33: =sum(J31:J32) -> 61236000 | K33: =sum(K31:K32) -> 80372250 | L33: =sum(L31:L32) -> 95642978 | M33: =sum(M31:M32) -> 1.1814721e+08
C34: Growth Rate (By Item) | D34: % | J34: =if(J33<>0,J33/I33-1,0) -> 0.26 | K34: =if(K33<>0,K33/J33-1,0) -> 0.3125 | L34: =if(L33<>0,L33/K33-1,0) -> 0.19 | M34: =if(M33<>0,M33/L33-1,0) -> 0.23529412
B36: D) Tempered glass (Sri racha)
C37: Product sell revenue | D37: THB | I37: =Data_Input!D47*Data_Input!D49 -> 0 | J37: =Data_Input!E47*Data_Input!E49 -> 0 | K37: =Data_Input!F47*Data_Input!F49 -> 0 | L37: =Data_Input!G47*Data_Input!G49 -> 0 | M37: =Data_Input!H47*Data_Input!H49 -> 0
C38: EPR revenue | D38: THB | E38: =Data_Input!$M$50 -> 0 | I38: =$E$38 -> 0 | J38: =$E$38 -> 0 | K38: =$E$38 -> 0 | L38: =$E$38 -> 0 | M38: =$E$38 -> 0
C39: Total Revenue (By Item) | D39: THB | I39: =sum(I37:I38) -> 0 | J39: =sum(J37:J38) -> 0 | K39: =sum(K37:K38) -> 0 | L39: =sum(L37:L38) -> 0 | M39: =sum(M37:M38) -> 0
C40: Growth Rate (By Item) | D40: % | J40: =if(J39<>0,J39/I39-1,0) -> 0 | K40: =if(K39<>0,K39/J39-1,0) -> 0 | L40: =if(L39<>0,L39/K39-1,0) -> 0 | M40: =if(M39<>0,M39/L39-1,0) -> 0
B42: E) Cullet (DL)
C43: Product sell revenue | D43: THB | I43: =Data_Input!D57*Data_Input!D59 -> 184800000 | J43: =Data_Input!E57*Data_Input!E59 -> 194040000 | K43: =Data_Input!F57*Data_Input!F59 -> 203742000 | L43: =Data_Input!G57*Data_Input!G59 -> 213929100 | M43: =Data_Input!H57*Data_Input!H59 -> 224625555
C44: EPR revenue | D44: THB | E44: =if($A$1="Best",Scenario!E$28,if($A$1="Base",Scenario!L$28,if($A$1="Worst",Scenario!S$28))) -> 0.2 | I44: =Data_Input!D57*$E$44 -> 9600000 | J44: =Data_Input!E57*$E$44 -> 9600000 | K44: =Data_Input!F57*$E$44 -> 9600000 | L44: =Data_Input!G57*$E$44 -> 9600000 | M44: =Data_Input!H57*$E$44 -> 9600000
C45: Total Revenue (By Item) | D45: THB | I45: =sum(I43:I44) -> 194400000 | J45: =sum(J43:J44) -> 203640000 | K45: =sum(K43:K44) -> 213342000 | L45: =sum(L43:L44) -> 223529100 | M45: =sum(M43:M44) -> 234225555
...

Sheet __scenarios
A1: Best case
A2: 1 | B2: Scenario 1 | C2: Scenario 2
A3: =N(Assumption_sheet!I13) -> 313200000
A4: =N(Assumption_sheet!I19) -> 7776000
A5: =N(Discount_Cal!C14) -> 0.070468104

Sheet Profit&Loss
E1: Profit and Lost Sheet
A3: Financial Projection บริษัท เค แอนด์ โอ ซิสเต็มส์ แอนด์ คอนซัลติ้ง จำกัด | F3: =F4+543 -> 2567 | G3: =G4+543 -> 2568 | H3: =H4+543 -> 2569 | I3: =I4+543 -> 2570 | J3: =J4+543 -> 2571 | K3: =K4+543 -> 2572
A4: year | F4: =YEAR(F6) -> 2024 | G4: =YEAR(G6) -> 2025 | H4: =YEAR(H6) -> 2026 | I4: =YEAR(I6) -> 2027 | J4: =YEAR(J6) -> 2028 | K4: =YEAR(K6) -> 2029
A5: Unit : THB. | D5: Unit | E5: Constant | F5: 0 | G5: =F5+1 -> 1 | H5: =G5+1 -> 2 | I5: =H5+1 -> 3 | J5: =I5+1 -> 4 | K5: =J5+1 -> 5
C6: peroid start | F6: 45292 | G6: =F7+1 -> 45658 | H6: =G7+1 -> 46023 | I6: =H7+1 -> 46388 | J6: =I7+1 -> 46753 | K6: =J7+1 -> 47119
C7: peroid end. | F7: =eomonth(F6,11) -> 45657 | G7: =eomonth(G6,11) -> 46022 | H7: =eomonth(H6,11) -> 46387 | I7: =eomonth(I6,11) -> 46752 | J7: =eomonth(J6,11) -> 47118 | K7: =eomonth(K6,11) -> 47483
A8: Profit Loss Account | F8: งบการเงิน
B9: รายได้จาการให้บริการ (Service Revenue) | D9: THB | F9: =Assumption_sheet!H60 -> 9.4270024e+08 | G9: =Assumption_sheet!I60 -> 1730902400 | H9: =Assumption_sheet!J60 -> 1957892000 | I9: =Assumption_sheet!K60 -> 2345082050 | J9: =Assumption_sheet!L60 -> 2654197378 | K9: =Assumption_sheet!M60 -> 2962171025
B10: รายได้อื่่น. (Other Revenue) | F10: 273287.06 | G10: 0 | H10: 0 | I10: 0 | J10: 0 | K10: 0
B11: รวมรายได้ | D11: THB | F11: =sum(F9:F10) -> 9.4297353e+08 | G11: =sum(G9+G10) -> 1730902400 | H11: =sum(H9+H10) -> 1957892000 | I11: =sum(I9+I10) -> 2345082050 | J11: =sum(J9+J10) -> 2654197378 | K11: =sum(K9+K10) -> 2962171025
B12: อัตราเติบโตของยอดขาย Revenue Growth | D12: % | G12: =Assumption_sheet!I16 | H12: =Assumption_sheet!J16 -> 0.16308244 | I12: =Assumption_sheet!K16 -> 0.36099384 | J12: =Assumption_sheet!L16 -> 0.12759925 | K12: =Assumption_sheet!M16 -> 0.12198793
B14: ต้นทุนการขาย (Cost of goods sold) | F14: =Assumption_sheet!H64 -> -8.7285018e+08 | G14: =Assumption_sheet!I64 -> -1592800000 | H14: =Assumption_sheet!J64 -> -1843312000 | I14: =Assumption_sheet!K64 -> -2170282750 | J14: =Assumption_sheet!L64 -> -2424027528 | K14: =Assumption_sheet!M64 -> -2678802588
B15: COGS Rate | D15: % | F15: =-F14/F9 -> 0.92590427 | G15: =-G14/G9 -> 0.92021364 | H15: =-H14/H9 -> 0.94147788 | I15: =-I14/I9 -> 0.92546133 | J15: =-J14/J9 -> 0.91328081 | K15: =-K14/K9 -> 0.90433758
B16: อัตราเติบโตของต้นทุนขาย COGS escaration Rate | D16: % | G16: =G15/F15-1 -> -0.0061460218 | H16: =H15/G15-1 -> 0.023107932 | I16: =I15/H15-1 -> -0.017012133 | J16: =J15/I15-1 -> -0.013161566 | K16: =K15/J15-1 -> -0.0097924153
B17: กำไรขั้นต้น (Gross Margin) | F17: =F11+F14 -> 70123351 | G17: =G11+G14 -> 138102400 | H17: =H11+H14 -> 114580000 | I17: =I11+I14 -> 174799300 | J17: =J11+J14 -> 230169850 | K17: =K11+K14 -> 2.8336844e+08
B18: สัดส่วนกำไรขั้นต้น (GOP Margin) | D18: % | F18: =F17/F11 -> 0.074364071 | G18: =G17/G11 -> 0.079786359 | H18: =H17/H11 -> 0.058522125 | I18: =I17/I11 -> 0.074538671 | J18: =J17/J11 -> 0.086719191 | K18: =K17/K11 -> 0.095662416
B20: ค่าใช้จ่ายในการขาย (Sale and marketing Expense) | D20: THB | F20: =Assumption_sheet!H116 -> -10996067
B21: สัดส่วนของค่าใช้จ่ายในการขาย | D21: % | F21: =-F20/F11 -> 0.011661056
B22: ค่าใช้จ่ายในการบริหาร ( Operate Expense) | D22: THB | F22: =Assumption_sheet!H117 -> -36936228
B23: สัดส่วนของค่าใช้จ่ายในการบริหาร | D23: % | F23: =-F22/F11 -> 0.039169952
B24: รวมค่าใช้จ่ายในการขายและบริหาร (Total Expense) | D24: THB | F24: =F20+F22-F30 -> -42165457 | G24: =Assumption_sheet!I118 -> -44145749 | H24: =Assumption_sheet!J118 -> -46322710 | I24: =Assumption_sheet!K118 -> -48721240 | J24: =Assumption_sheet!L118 -> -51370098 | K24: =Assumption_sheet!M118 -> -54302612
B25: สัดส่วนของค่าใช้จ่ายในการขายและบริหาร | D25: % | F25: =-F24/F11 -> 0.044715419 | G25: =Assumption_sheet!I119 -> 0.046964801 | H25: =Assumption_sheet!J119 -> 0.049313042 | I25: =Assumption_sheet!K119 -> 0.051778694 | J25: =Assumption_sheet!L119 -> 0.054367628 | K25: =Assumption_sheet!M119 -> 0.05708601
B27: กำไรก่อนหักดอกเบี้ยจ่าย ภาษี และ ค่าเสื่อม (EBITDA) | D27: THB | F27: =sum(F17+F24) -> 27957894 | G27: =sum(G17+G24) -> 93956651 | H27: =sum(H17+H24) -> 68257290 | I27: =sum(I17+I24) -> 1.2607806e+08 | J27: =sum(J17+J24) -> 1.7879975e+08 | K27: =sum(K17+K24) -> 2.2906583e+08
B28: สัดส่วน EBITDA Margin | D28: % | F28: =F27/F$11 -> 0.029648652 | G28: =G27/G11 -> 0.054281888 | H28: =H27/H11 -> 0.034862643 | I28: =I27/I11 -> 0.05376275 | J28: =J27/J11 -> 0.067364904 | K28: =K27/K11 -> 0.077330385
B30: Depreation | F30: =Assumption_sheet!H170 -> -5766838 | G30: =Assumption_sheet!I170 -> -6342382.5 | H30: =Assumption_sheet!J170 -> -6337991.8 | I30: =Assumption_sheet!K170 -> -3804500 | J30: =Assumption_sheet!L170 -> -3508816.8 | K30: =Assumption_sheet!M170 -> -3436104.5
B31: Deprea.CAPEX | G31: =Assumption_sheet!I172 -> -1000000 | H31: =Assumption_sheet!J172 -> -2000000 | I31: =Assumption_sheet!K172 -> -3000000 | J31: =Assumption_sheet!L172 -> -4000000 | K31: =Assumption_sheet!M172 -> -5000000
B32: กำไรก่อนหักต้นทุนทางการเงินและภาษี (EBIT) | F32: =F27+F30 -> 22191056 | G32: =sum(G27,G30,G31) -> 86614268 | H32: =H27+H30 -> 61919298 | I32: =I27+I30 -> 1.2227356e+08 | J32: =J27+J30 -> 1.7529094e+08 | K32: =K27+K30 -> 225629721
B33: EBIT Margin | D33: % | F33: =F32/F$11 -> 0.023533063 | G33: =G32/G$11 -> 0.050039949 | H33: =H32/H$11 -> 0.031625492 | I33: =I32/I$11 -> 0.052140419 | J33: =J32/J$11 -> 0.066042916 | K33: =K32/K$11 -> 0.07617039
B36: ต้นทุนทางการเงิน (Interester Expense) | F36: =Assumption_sheet!H203 -> -3874174 | G36: =Assumption_sheet!I203 -> -3466218.7 | H36: =Assumption_sheet!J203 -> -3358045.7 | I36: =Assumption_sheet!K203 -> -3249872.7 | J36: =Assumption_sheet!L203 -> -3141699.7 | K36: =Assumption_sheet!M203 -> -3087613.2
B37: กำไรก่อนหักภาษีนิติบุคคน (Earning before tax) | F37: =F32+F36 -> 18316882 | G37: =G32+G36 -> 83148050 | H37: =H32+H36 -> 58561252 | I37: =I32+I36 -> 1.1902369e+08 | J37: =J32+J36 -> 1.7214924e+08 | K37: =K32+K36 -> 2.2254211e+08
B38: EBT Margin | D38: % | F38: =F37/F11 -> 0.019424598 | G38: =G37/G11 -> 0.048037399 | H38: =H37/H11 -> 0.029910359 | I38: =I37/I11 -> 0.050754594 | J38: =J37/J11 -> 0.064859244 | K38: =K37/K11 -> 0.075128042
B40: ภาษีเงินได้นิติบุคคล (Corpertate income tax) | F40: -4094506.7 | G40: =-G37*Assumption_sheet!$I$121 -> -20787012 | H40: =-H37*Assumption_sheet!$I$121 -> -14640313 | I40: =-I37*Assumption_sheet!$I$121 -> -29755922 | J40: =-J37*Assumption_sheet!$I$121 -> -43037309 | K40: =-K37*Assumption_sheet!$I$121 -> -55635527
B41: Tax Rate | F41: =-F40/F37 -> 0.22353732 | G41: =-G40/G37 -> 0.25 | H41: =-H40/H37 -> 0.25 | I41: =-I40/I37 -> 0.25 | J41: =-J40/J37 -> 0.25 | K41: =-K40/K37 -> 0.25
B42: กำไรสุทธิ Net Profit margin | F42: =F37+F40 -> 14222375 | G42: =G37+G40 -> 62361037 | H42: =H37+H40 -> 43920939 | I42: =I37+I40 -> 89267766 | J42: =J37+J40 -> 1.2911193e+08 | K42: =K37+K40 -> 1.6690658e+08
B43: NP Margin | D43: % | F43: =F42/F11 -> 0.015082475 | G43: =G42/G11 -> 0.036028049 | H43: =H42/H11 -> 0.022432769 | I43: =I42/I11 -> 0.038065946 | J43: =J42/J11 -> 0.048644433 | K43: =K42/K11 -> 0.056346031

Sheet BalancSheet
A1: Financial Projection บริษัท เค แอนด์ โอ ซิสเต็มส์ แอนด์ คอนซัลติ้ง จำกัด | F1: =F2+543 -> 2567 | G1: =G2+543 -> 2568 | H1: =H2+543 -> 2569 | I1: =I2+543 -> 2570 | J1: =J2+543 -> 2571 | K1: =K2+543 -> 2572
A2: year | F2: =YEAR(F4) -> 2024 | G2: =YEAR(G4) -> 2025 | H2: =YEAR(H4) -> 2026 | I2: =YEAR(I4) -> 2027 | J2: =YEAR(J4) -> 2028 | K2: =YEAR(K4) -> 2029
A3: Unit : THB. | D3: Unit | E3: Constant | F3: 0 | G3: =F3+1 -> 1 | H3: =G3+1 -> 2 | I3: =H3+1 -> 3 | J3: =I3+1 -> 4 | K3: =J3+1 -> 5
C4: peroid start | F4: 45292 | G4: =F5+1 -> 45658 | H4: =G5+1 -> 46023 | I4: =H5+1 -> 46388 | J4: =I5+1 -> 46753 | K4: =J5+1 -> 47119
C5: peroid end. | F5: =eomonth(F4,11) -> 45657 | G5: =eomonth(G4,11) -> 46022 | H5: =eomonth(H4,11) -> 46387 | I5: =eomonth(I4,11) -> 46752 | J5: =eomonth(J4,11) -> 47118 | K5: =eomonth(K4,11) -> 47483
A7: Balanc Sheet
B8: เงินสดหรือเทียบเท่า (Cash and Cash Equivalent) | F8: =Assumption_sheet!E127 -> 16443308 | G8: =CashflowStatement!G24 -> -62803416 | H8: =CashflowStatement!H24 -> -52143831 | I8: =CashflowStatement!I24 -> -11685919 | J8: =CashflowStatement!J24 -> 78614015 | K8: =CashflowStatement!K24 -> 2.0963109e+08
B9: ลูกหนี้การค้า (Account Reciveable) | F9: =Assumption_sheet!E130 -> 35033774 | G9: ='Profit&Loss'!G9*Assumption_sheet!I124/365 -> 94843967 | H9: ='Profit&Loss'!H9*Assumption_sheet!J124/365 -> 1.0728175e+08 | I9: ='Profit&Loss'!I9*Assumption_sheet!K124/365 -> 1.2849765e+08 | J9: ='Profit&Loss'!J9*Assumption_sheet!L124/365 -> 1.4543547e+08 | K9: ='Profit&Loss'!K9*Assumption_sheet!M124/365 -> 1.6231074e+08
B10: สินค้าคงเหลือ (Inventory) ที่ดินมีไว้เพื่อขาย | F10: =Assumption_sheet!E131 -> 50068562 | G10: =-'Profit&Loss'!G14*Assumption_sheet!I125/365 -> 1.3091507e+08 | H10: =-'Profit&Loss'!H14*Assumption_sheet!J125/365 -> 1.515051e+08 | I10: =-'Profit&Loss'!I14*Assumption_sheet!K125/365 -> 1.783794e+08 | J10: =-'Profit&Loss'!J14*Assumption_sheet!L125/365 -> 1.9923514e+08 | K10: =-'Profit&Loss'!K14*Assumption_sheet!M125/365 -> 2.2017556e+08
B11: ที่ดิน อาคาร อุปกรณ์(Property plant and equipment) | F11: =sum(Assumption_sheet!E144,Assumption_sheet!E149) -> 84059236 | G11: =sum(F11,Assumption_sheet!I170,-CashflowStatement!G16,-CashflowStatement!G10) -> 86716853 | H11: =sum(G11,Assumption_sheet!J170,-CashflowStatement!H16,-CashflowStatement!H10) -> 88378861 | I11: =sum(H11,Assumption_sheet!K170,-CashflowStatement!I16,-CashflowStatement!I10) -> 91574361 | J11: =sum(I11,Assumption_sheet!L170,-CashflowStatement!J16,-CashflowStatement!J10) -> 94065545 | K11: =sum(J11,Assumption_sheet!M170,-CashflowStatement!K16,-CashflowStatement!K10) -> 95629440
B12: รวมสินทรัพย์ (Total Asset) | F12: =SUM(F8:F11) -> 1.8560488e+08 | G12: =SUM(G8:G11) -> 249672473 | H12: =SUM(H8:H11) -> 2.9502188e+08 | I12: =SUM(I8:I11) -> 3.8676549e+08 | J12: =SUM(J8:J11) -> 5.1735017e+08 | K12: =SUM(K8:K11) -> 6.8774682e+08
B13: เจ้าหนี้การค้า (Account Payable) | F13: =Assumption_sheet!E175 -> 18109418 | G13: =-'Profit&Loss'!G14*Assumption_sheet!I126/365 -> 21819178 | H13: =-'Profit&Loss'!H14*Assumption_sheet!J126/365 -> 25250849 | I13: =-'Profit&Loss'!I14*Assumption_sheet!K126/365 -> 29729901 | J13: =-'Profit&Loss'!J14*Assumption_sheet!L126/365 -> 33205857 | K13: =-'Profit&Loss'!K14*Assumption_sheet!M126/365 -> 36695926
B14: เจ้าหนี้สถาบันการเงิน (Bank Dept) | F14: =sum(Assumption_sheet!E180,Assumption_sheet!E183) -> 65190837 | G14: =F14+(Assumption_sheet!I192+Assumption_sheet!I199) -> 63187633 | H14: =G14+(Assumption_sheet!J192+Assumption_sheet!J199) -> 61184429 | I14: =H14+(Assumption_sheet!K192+Assumption_sheet!K199) -> 59181225 | J14: =I14+(Assumption_sheet!L192+Assumption_sheet!L199) -> 57178021 | K14: =J14+(Assumption_sheet!M192+Assumption_sheet!M199) -> 57178021
B15: รวมหนี้สิน Total Liabillity | F15: =SUM(F13:F14) -> 83300255 | G15: =SUM(G13:G14) -> 85006811 | H15: =SUM(H13:H14) -> 86435278 | I15: =SUM(I13:I14) -> 88911126 | J15: =SUM(J13:J14) -> 90383878 | K15: =SUM(K13:K14) -> 93873947
B16: ส่วนของเจ้าของ (Paid up capital) | F16: =(Assumption_sheet!E150-Assumption_sheet!E187)+Assumption_sheet!$E$127 -> 1.0230462e+08 | G16: =F16 -> 1.0230462e+08 | H16: =G16 -> 1.0230462e+08 | I16: =H16 -> 1.0230462e+08 | J16: =I16 -> 1.0230462e+08 | K16: =J16 -> 1.0230462e+08
B17: กำไร(ขาดทุน)สะสม (Retained earning) | F17: 0 | G17: =F17+'Profit&Loss'!G42 -> 62361037 | H17: =G17+'Profit&Loss'!H42 -> 1.0628198e+08 | I17: =H17+'Profit&Loss'!I42 -> 1.9554974e+08 | J17: =I17+'Profit&Loss'!J42 -> 3.2466167e+08 | K17: =J17+'Profit&Loss'!K42 -> 4.9156825e+08
B18: รวมส่วนของเจ้าของ (Total equity) | F18: =sum(F16:F17) -> 1.0230462e+08 | G18: =sum(G16:G17) -> 164665662 | H18: =sum(H16:H17) -> 2.085866e+08 | I18: =sum(I16:I17) -> 2.9785437e+08 | J18: =sum(J16:J17) -> 4.2696629e+08 | K18: =sum(K16:K17) -> 5.9387287e+08
B19: รวมหนี้สินและส่วนของเจ้าของTotal liabillity and equity | F19: =F15+F18 -> 1.8560488e+08 | G19: =G15+G18 -> 249672473 | H19: =H15+H18 -> 2.9502188e+08 | I19: =I15+I18 -> 3.8676549e+08 | J19: =J15+J18 -> 5.1735017e+08 | K19: =K15+K18 -> 6.8774682e+08
B20: Check | F20: =F12-F19 -> 2.9802322e-08 | G20: =G12-G19 -> 0 | H20: =H12-H19 -> 5.9604645e-08 | I20: =I12-I19 -> 0 | J20: =J12-J19 -> 0 | K20: =K12-K19 -> 1.1920929e-07

Sheet CashflowStatement
A1: Financial Projection บริษัท เค แอนด์ โอ ซิสเต็มส์ แอนด์ คอนซัลติ้ง จำกัด | F1: =F2+543 -> 2567 | G1: =G2+543 -> 2568 | H1: =H2+543 -> 2569 | I1: =I2+543 -> 2570 | J1: =J2+543 -> 2571 | K1: =K2+543 -> 2572
A2: year | F2: =YEAR(F4) -> 2024 | G2: =YEAR(G4) -> 2025 | H2: =YEAR(H4) -> 2026 | I2: =YEAR(I4) -> 2027 | J2: =YEAR(J4) -> 2028 | K2: =YEAR(K4) -> 2029
A3: Unit : THB. | D3: Unit | E3: Constant | F3: 0 | G3: =F3+1 -> 1 | H3: =G3+1 -> 2 | I3: =H3+1 -> 3 | J3: =I3+1 -> 4 | K3: =J3+1 -> 5
C4: peroid start | F4: 45292 | G4: =F5+1 -> 45658 | H4: =G5+1 -> 46023 | I4: =H5+1 -> 46388 | J4: =I5+1 -> 46753 | K4: =J5+1 -> 47119
C5: peroid end. | F5: =eomonth(F4,11) -> 45657 | G5: =eomonth(G4,11) -> 46022 | H5: =eomonth(H4,11) -> 46387 | I5: =eomonth(I4,11) -> 46752 | J5: =eomonth(J4,11) -> 47118 | K5: =eomonth(K4,11) -> 47483
A6: Cashflow statment
B7: EBIT | F7: 0 | G7: ='Profit&Loss'!G32 -> 86614268 | H7: ='Profit&Loss'!H32 -> 61919298 | I7: ='Profit&Loss'!I32 -> 1.2227356e+08 | J7: ='Profit&Loss'!J32 -> 1.7529094e+08 | K7: ='Profit&Loss'!K32 -> 225629721
B8: ( - ) ภาษีนิติบุคคล (Corporate income tax) | F8: 0 | G8: ='Profit&Loss'!G40 -> -20787012 | H8: ='Profit&Loss'!H40 -> -14640313 | I8: ='Profit&Loss'!I40 -> -29755922 | J8: ='Profit&Loss'!J40 -> -43037309 | K8: ='Profit&Loss'!K40 -> -55635527
B9: ( + ) ค่าเสื่อมราคา (Depreciation) | F9: 0 | G9: =-'Profit&Loss'!G30 -> 6342382.5 | H9: =-'Profit&Loss'!H30 -> 6337991.8 | I9: =-'Profit&Loss'!I30 -> 3804500 | J9: =-'Profit&Loss'!J30 -> 3508816.8 | K9: =-'Profit&Loss'!K30 -> 3436104.5
B10: ( + ) ค่าเสื่อมราคา (Depre.CAPEX) | F10: 0 | G10: =-'Profit&Loss'!G31 -> 1000000 | H10: =-'Profit&Loss'!H31 -> 2000000 | I10: =-'Profit&Loss'!I31 -> 3000000 | J10: =-'Profit&Loss'!J31 -> 4000000 | K10: =-'Profit&Loss'!K31 -> 5000000
B11: ( +/- ) ลูกหนี้การค้า (Account receivable) | F11: -35033774 | G11: =BalancSheet!F9-BalancSheet!G9 -> -59810193 | H11: =BalancSheet!G9-BalancSheet!H9 -> -12437786 | I11: =BalancSheet!H9-BalancSheet!I9 -> -21215893 | J11: =BalancSheet!I9-BalancSheet!J9 -> -16937826 | K11: =BalancSheet!J9-BalancSheet!K9 -> -16875268
B12: ( +/- ) ทรัพย์ที่มีไว้เพื่อขาย Inventory | F12: -50068562 | G12: =BalancSheet!F10-BalancSheet!G10 -> -80846507 | H12: =BalancSheet!G10-BalancSheet!H10 -> -20590027 | I12: =BalancSheet!H10-BalancSheet!I10 -> -26874308 | J12: =BalancSheet!I10-BalancSheet!J10 -> -20855735 | K12: =BalancSheet!J10-BalancSheet!K10 -> -20940416
B13: ( +/- ) เจ้าหนี้การค้า Account payable | F13: 18109418 | G13: =BalancSheet!G13-BalancSheet!F13 -> 3709760.3 | H13: =BalancSheet!H13-BalancSheet!G13 -> 3431671.2 | I13: =BalancSheet!I13-BalancSheet!H13 -> 4479051.4 | J13: =BalancSheet!J13-BalancSheet!I13 -> 3475955.9 | K13: =BalancSheet!K13-BalancSheet!J13 -> 3490069.3
B14: เงินสดจากการดำเนินงาน (Cash flow from operation) | F14: 0 | G14: =sum(G7:G13) -> -63777301 | H14: =sum(H7:H13) -> 26020834 | I14: =sum(I7:I13) -> 55710988 | J14: =sum(J7:J13) -> 1.0544484e+08 | K14: =sum(K7:K13) -> 1.4410468e+08
B15: เงินลงทุนในสินทรัพย์ระยะยาว (Capex) | F15: =-sum(Assumption_sheet!E135:E139) -> -28320029 | G15: =Data_Input!R17 -> -10000000 | H15: =Data_Input!S17 -> -10000000 | I15: =Data_Input!T17 -> -10000000 | J15: =Data_Input!U17 -> -10000000 | K15: =Data_Input!V17 -> -10000000
B16: เงินสดจากการลงทุน Cash flow from investing | F16: =F15 -> -28320029 | G16: =G15 -> -10000000 | H16: =H15 -> -10000000 | I16: =I15 -> -10000000 | J16: =J15 -> -10000000 | K16: =K15 -> -10000000
B17: Debt drawdown | F17: =Assumption_sheet!E187 -> 83300255 | G17: =Assumption_sheet!I191 -> 0 | H17: =Assumption_sheet!J191 -> 0 | I17: =Assumption_sheet!K191 -> 0 | J17: =Assumption_sheet!L191 -> 0 | K17: =Assumption_sheet!M191 -> 0
B18: Debt repayment | F18: 0 | G18: =(Assumption_sheet!I192+Assumption_sheet!I199) -> -2003203.9 | H18: =(Assumption_sheet!J192+Assumption_sheet!J199) -> -2003203.9 | I18: =(Assumption_sheet!K192+Assumption_sheet!K199) -> -2003203.9 | J18: =(Assumption_sheet!L192+Assumption_sheet!L199) -> -2003203.9 | K18: =(Assumption_sheet!M192+Assumption_sheet!M199) -> 0
B19: Interest expense | F19: 0 | G19: ='Profit&Loss'!G36 -> -3466218.7 | H19: ='Profit&Loss'!H36 -> -3358045.7 | I19: ='Profit&Loss'!I36 -> -3249872.7 | J19: ='Profit&Loss'!J36 -> -3141699.7 | K19: ='Profit&Loss'!K36 -> -3087613.2
B20: Capital injection | F20: =Assumption_sheet!E150-Assumption_sheet!E187 -> 85861317 | G20: 0 | H20: 0 | I20: 0 | J20: 0 | K20: 0
B21: Cash flow from financing | F21: =sum(F17:F20) -> 1.6916157e+08 | G21: =sum(G17:G20) -> -5469422.5 | H21: =sum(H17:H20) -> -5361249.5 | I21: =sum(I17:I20) -> -5253076.5 | J21: =sum(J17:J20) -> -5144903.5 | K21: =sum(K17:K20) -> -3087613.2
B22: Beginning cash flow | F22: =Assumption_sheet!E127 -> 16443308 | G22: =F24 -> 16443308 | H22: =G24 -> -62803416 | I22: =H24 -> -52143831 | J22: =I24 -> -11685919 | K22: =J24 -> 78614015
B23: Change in cash | F23: 0 | G23: =sum(G14,G16,G21) -> -79246724 | H23: =H14+H16+H21 -> 10659585 | I23: =I14+I16+I21 -> 40457912 | J23: =J14+J16+J21 -> 90299934 | K23: =K14+K16+K21 -> 1.3101707e+08
B24: Ending cash flow | F24: =sum(F22:F23) -> 16443308 | G24: =sum(G22:G23) -> -62803416 | H24: =sum(H22:H23) -> -52143831 | I24: =sum(I22:I23) -> -11685919 | J24: =sum(J22:J23) -> 78614015 | K24: =sum(K22:K23) -> 2.0963109e+08

Sheet ProjectReturn
A1: Financial Projection บริษัท เค แอนด์ โอ ซิสเต็มส์ แอนด์ คอนซัลติ้ง จำกัด | F1: =F2+543 -> 2567 | G1: =G2+543 -> 2568 | H1: =H2+543 -> 2569 | I1: =I2+543 -> 2570 | J1: =J2+543 -> 2571 | K1: =K2+543 -> 2572
A2: year | F2: =YEAR(F4) -> 2024 | G2: =YEAR(G4) -> 2025 | H2: =YEAR(H4) -> 2026 | I2: =YEAR(I4) -> 2027 | J2: =YEAR(J4) -> 2028 | K2: =YEAR(K4) -> 2029
A3: Unit : THB. | D3: Unit | E3: Constant | F3: 0 | G3: =F3+1 -> 1 | H3: =G3+1 -> 2 | I3: =H3+1 -> 3 | J3: =I3+1 -> 4 | K3: =J3+1 -> 5
C4: peroid start | F4: 45292 | G4: =F5+1 -> 45658 | H4: =G5+1 -> 46023 | I4: =H5+1 -> 46388 | J4: =I5+1 -> 46753 | K4: =J5+1 -> 47119
C5: peroid end. | F5: =eomonth(F4,11) -> 45657 | G5: =eomonth(G4,11) -> 46022 | H5: =eomonth(H4,11) -> 46387 | I5: =eomonth(I4,11) -> 46752 | J5: =eomonth(J4,11) -> 47118 | K5: =eomonth(K4,11) -> 47483
A7: Project return
B9: EBIT | F9: 0 | G9: ='Profit&Loss'!G32 -> 86614268 | H9: ='Profit&Loss'!H32 -> 61919298 | I9: ='Profit&Loss'!I32 -> 1.2227356e+08 | J9: ='Profit&Loss'!J32 -> 1.7529094e+08 | K9: ='Profit&Loss'!K32 -> 225629721
B10: (-) Corporate Tax | F10: 0 | G10: =-G9*Assumption_sheet!$E$121 -> -21653567 | H10: =-H9*Assumption_sheet!$E$121 -> -15479824 | I10: =-I9*Assumption_sheet!$E$121 -> -30568390 | J10: =-J9*Assumption_sheet!$E$121 -> -43822734 | K10: =-K9*Assumption_sheet!$E$121 -> -56407430
B11: (+) Depreciation | F11: =CashflowStatement!F9 -> 0 | G11: =CashflowStatement!G9 -> 6342382.5 | H11: =CashflowStatement!H9 -> 6337991.8 | I11: =CashflowStatement!I9 -> 3804500 | J11: =CashflowStatement!J9 -> 3508816.8 | K11: =CashflowStatement!K9 -> 3436104.5
B12: ( + ) ค่าเสื่อมราคา (Depre.CAPEX) | F12: =CashflowStatement!F10 -> 0 | G12: =CashflowStatement!G10 -> 1000000 | H12: =CashflowStatement!H10 -> 2000000 | I12: =CashflowStatement!I10 -> 3000000 | J12: =CashflowStatement!J10 -> 4000000 | K12: =CashflowStatement!K10 -> 5000000
B13: (+/-)Change in working capital | F13: =sum(CashflowStatement!F11:F13) -> -66992918 | G13: =sum(CashflowStatement!G11:G13) -> -1.3694694e+08 | H13: =sum(CashflowStatement!H11:H13) -> -29596142 | I13: =sum(CashflowStatement!I11:I13) -> -43611150 | J13: =sum(CashflowStatement!J11:J13) -> -34317605 | K13: =sum(CashflowStatement!K11:K13) -> -34325615
B14: Cashflow from operation | F14: =sum(F9:F13) -> -66992918 | G14: =sum(G9:G13) -> -64643856 | H14: =sum(H9:H13) -> 25181323 | I14: =sum(I9:I13) -> 54898520 | J14: =sum(J9:J13) -> 1.0465941e+08 | K14: =sum(K9:K13) -> 1.4333278e+08
B16: Capex | F16: =CashflowStatement!F16 -> -28320029 | G16: =CashflowStatement!G15 -> -10000000 | H16: =CashflowStatement!H15 -> -10000000 | I16: =CashflowStatement!I15 -> -10000000 | J16: =CashflowStatement!J15 -> -10000000 | K16: =CashflowStatement!K15 -> -10000000
B17: Free cash flow to firm (FCFF) | F17: =F14+F16 -> -95312946 | G17: =G14+G16 -> -74643856 | H17: =H14+H16 -> 15181323 | I17: =I14+I16 -> 44898520 | J17: =J14+J16 -> 94659413 | K17: =K14+K16 -> 1.3333278e+08
B19: Net borrowing | F19: =CashflowStatement!F17 -> 83300255 | G19: =sum(CashflowStatement!G17:G18) -> -2003203.9 | H19: =sum(CashflowStatement!H17:H18) -> -2003203.9 | I19: =sum(CashflowStatement!I17:I18) -> -2003203.9 | J19: =sum(CashflowStatement!J17:J18) -> -2003203.9 | K19: =sum(CashflowStatement!K17:K18) -> 0
B20: Interest expense | F20: =CashflowStatement!F19 -> 0 | G20: =CashflowStatement!G19 -> -3466218.7 | H20: =CashflowStatement!H19 -> -3358045.7 | I20: =CashflowStatement!I19 -> -3249872.7 | J20: =CashflowStatement!J19 -> -3141699.7 | K20: =CashflowStatement!K19 -> -3087613.2
B21: Free cashflow to equity (FCFE) | F21: =F17+F19+F20 -> -12012692 | G21: =G17+G19+G20 -> -80113279 | H21: =H17+H19+H20 -> 9820073.1 | I21: =I17+I19+I20 -> 39645444 | J21: =J17+J19+J20 -> 89514509 | K21: =K17+K19+K20 -> 1.3024517e+08
B23: FCFF Terminal Value | K23: =K17*(1+Assumption_sheet!E10)/(Discount_Cal!C14 - Assumption_sheet!E10) -> 6839882017
B24: FCFE Terminal Value | K24: =K21*(1+Assumption_sheet!E10)/(Discount_Cal!C11 - Assumption_sheet!E10) -> 3752433133
B26: FCFF+Terminal Value | F26: =F17+F24 -> -95312946 | G26: =G17+G24 -> -74643856 | H26: =H17+H24 -> 15181323 | I26: =I17+I24 -> 44898520 | J26: =J17+J24 -> 94659413 | K26: =K17+K23 -> 6973214797
B27: FCFE+Terminal Value | F27: =F21+F24 -> -12012692 | G27: =G21+G24 -> -80113279 | H27: =H21+H24 -> 9820073.1 | I27: =I21+I24 -> 39645444 | J27: =J21+J24 -> 89514509 | K27: =K21+K24 -> 3882678300
B29: Project IRR | D29: x | E29: =irr(F26:K26) -> 1.2616251 | G29: Valuation FCFF | J29: Valuation FCFE
B30: Equity IRR | D30: x | E30: =irr(F27:K27) -> 1.5292148 | G30: Enterprise Value | H30: {=npv(Discount_Cal!$C$14,G26:K26)} -> 5013154429 | J30: Equity Value | K30: {=npv(Discount_Cal!$G$15,G27:K27)} -> 2594775466
G31: (+)Cash | H31: =CashflowStatement!F22 -> 16443308
B32: Project NPV | D32: x | E32: {=npv(Discount_Cal!$C$14,G26:K26)+F26} -> 4917841482 | G32: (-)Dept | H32: =-Assumption_sheet!E187 -> -83300255
B33: Equity NPV | D33: x | E33: {=npv(Discount_Cal!$C$11,G27:K27)+F27} -> 2582762774 | G33: Equity Value | H33: =sum(H30:H32) -> 4946297482
B35: FCFF | F35: =F26 -> -95312946 | G35: =G26 -> -74643856 | H35: =H26 -> 15181323 | I35: =I26 -> 44898520 | J35: =J26 -> 94659413 | K35: =K26 -> 6973214797
B36: Accumulated FCFF | F36: =F35+E36 -> -95312946 | G36: =G35+F36 -> -1.699568e+08 | H36: =H35+G36 -> -1.5477548e+08 | I36: =I35+H36 -> -1.0987696e+08 | J36: =J35+I36 -> -15217547 | K36: =K35+J36 -> 6957997250
F37: =IF(AND(E36<0,F36>=0),F3-1+(E36*-1/F35),0) -> 0 | G37: =IF(AND(F36<0,G36>=0),G3-1+(F36*-1/G35),0) -> 0 | H37: =IF(AND(G36<0,H36>=0),H3-1+(G36*-1/H35),0) -> 0 | I37: =IF(AND(H36<0,I36>=0),I3-1+(H36*-1/I35),0) -> 0 | J37: =IF(AND(I36<0,J36>=0),J3-1+(I36*-1/J35),0) -> 0 | K37: =IF(AND(J36<0,K36>=0),K3-1+(J36*-1/K35),0) -> 4.0021823
B38: FCFE | F38: =F27 -> -12012692 | G38: =G27 -> -80113279 | H38: =H27 -> 9820073.1 | I38: =I27 -> 39645444 | J38: =J27 -> 89514509 | K38: =K27 -> 3882678300
B39: Accumulated FCFE | F39: =F38+E39 -> -12012692 | G39: =G38+F39 -> -92125970 | H39: =H38+G39 -> -82305897 | I39: =I38+H39 -> -42660454 | J39: =J38+I39 -> 46854055 | K39: =K38+J39 -> 3929532355
F40: =IF(AND(E39<0,F39>=0),F3-1+(E39*-1/F38),0) -> 0 | G40: =IF(AND(F39<0,G39>=0),G3-1+(F39*-1/G38),0) -> 0 | H40: =IF(AND(G39<0,H39>=0),H3-1+(G39*-1/H38),0) -> 0 | I40: =IF(AND(H39<0,I39>=0),I3-1+(H39*-1/I38),0) -> 0 | J40: =IF(AND(I39<0,J39>=0),J3-1+(I39*-1/J38),0) -> 3.4765759 | K40: =IF(AND(J39<0,K39>=0),K3-1+(J39*-1/K38),0) -> 0
B41: Project payback period | D41: Year | E41: =sum(F37:K37) -> 4.0021823
B42: Equity Payback period | D42: Year | E42: =sum(F40:K40) -> 3.4765759
F45: สรุป
F46: - จากการลงทุนในโครงการนี้ ผู้ลงทุนจะได้รับผลตอบแทนจากการลงทุนดังต่อไปนี้
G47: - อัตราผลตอบแทนจากการลงทุนทั้งโครงการ (Project IRR) | K47: =E29 -> 1.2616251
G48: - อัตราผลตอบแทนจากเงินลงทุน (Equity IRR) | K48: =E30 -> 1.5292148
F50: - จากการประเมินมูลค่าของกิจการ ณ ปัจจุบัน มีราคาที่เหมาะสม ดังนี้
G51: - มูลค่าที่เหมาะสมตามกระแสเงินสดอิสระของกิจการเท่ากับ | K51: =H33 -> 4946297482 | L51: บาท
...

Sheet Discount_Cal
F1: Formula
F2: Terminal Value | G2: TV=(Fcfปีสุดท้าย*(1+g) / (ke-g)
F3: (CAPM) : Cost of equity (ke) = risk free rate (rf) + Beta (Return market (Rm) - risk free rate (rf))
B4: Discount rate calculation | F4: Risk free rate = government bond/yield 10yr - 20yr, THAIBMA
F5: Beta = Volatility
B6: WACC - Weighted average cost of capital | F6: Return market = Average return of SET index 10yr - 20yr
B7: Cost of equity - ต้นทุนของผู้ถือหุ้น | F7: Adjust country risk premium, construction premium, illliquidity premium
B8: Cost of debt - ต้นทุนเจ้าหนี้
B10: Weight equity | C10: =1-Assumption_sheet!E178 -> 0.50756987 | F10: CAPM (Capital asset pricing model)
B11: Ke | C11: =G15 -> 0.086445 | F11: สมมติฐาน (Assumption)
B12: Weight debt | C12: =Assumption_sheet!E178 -> 0.49243013 | F12: risk free rate (rf) | G12: 0.0427 | H12: ผลตอบแทนพันธบัตรรัฐบาลสหรัฐฯ อายุ 10 ปี ณ วันที่ 11 สิงหาคม 2025 อยู่ที่ 4.27%
B13: Kd | C13: =G16 -> 0.054 | F13: beta | G13: 0.65 | H13: อ้างอิงข้อมูลของบริษัท E&E Recycling (จดทะเบียนในตลาด TPEX) โดยมีค่า Beta (5-year) อยู่ที่ 0.65
B14: WACC | C14: 0.070468104 | F14: return market (rm) | G14: 0.11 | H14: อัตราผลตอบแทนที่นักลงทุนคาดหวัง โดยอ้างอิงผลตอบแทนเฉลี่ยย้อนหลัง 10 ปี ของ S&P500
F15: cost of equity (ke) | G15: =G12+G13*(G14-G12) -> 0.086445
F16: cost of dept (kd) | G16: =Assumption_sheet!E181 -> 0.054 | H16: อ้างอิงจากอัตราดอกเบี้ยเงินกู้ของกิจการ

Sheet Drepre.CAPEX
A3: ปีลงทุน | B3: เงินลงทุน | C3: อายุการใช้งาน | D3: 2025 | E3: 2026 | F3: 2027 | G3: 2028 | H3: 2029 | I3: 2030 | J3: 2031 | K3: 2032 | L3: 2033 | M3: 2034 | N3: 2035 | O3: 2036 | P3: 2037 | Q3: 2038 | R3: 2039
A4: 2025 | B4: =-Data_Input!R17 -> 10000000 | C4: 10 | D4: =IF(AND(D3>=A4,D3<A4+C4),B4/C4,0) -> 1000000 | E4: =IF(AND(E3>=A4,E3<A4+C4),B4/C4,0) -> 1000000 | F4: =IF(AND(F3>=A4,F3<A4+C4),B4/C4,0) -> 1000000 | G4: =IF(AND(G3>=A4,G3<A4+C4),B4/C4,0) -> 1000000 | H4: =IF(AND(H3>=A4,H3<A4+C4),B4/C4,0) -> 1000000 | I4: =IF(AND(I3>=A4,I3<A4+C4),B4/C4,0) -> 1000000 | J4: =IF(AND(J3>=A4,J3<A4+C4),B4/C4,0) -> 1000000 | K4: =IF(AND(K3>=A4,K3<A4+C4),B4/C4,0) -> 1000000 | L4: =IF(AND(L3>=A4,L3<A4+C4),B4/C4,0) -> 1000000 | M4: =IF(AND(M3>=A4,M3<A4+C4),B4/C4,0) -> 1000000 | N4: =IF(AND(N3>=A4,N3<A4+C4),B4/C4,0) -> 0 | O4: =IF(AND(O3>=A4,O3<A4+C4),B4/C4,0) -> 0 | P4: =IF(AND(P3>=A4,P3<A4+C4),B4/C4,0) -> 0 | Q4: =IF(AND(Q3>=A4,Q3<A4+C4),B4/C4,0) -> 0 | R4: =IF(AND(R3>=A4,R3<A4+C4),B4/C4,0) -> 0
A5: 2026 | B5: =-Data_Input!S17 -> 10000000 | C5: 10 | D5: =IF(AND(D3>=A5,D3<A5+C5),B5/C5,0) -> 0 | E5: =IF(AND(E3>=A5,E3<A5+C5),B5/C5,0) -> 1000000 | F5: =IF(AND(F3>=A5,F3<A5+C5),B5/C5,0) -> 1000000 | G5: =IF(AND(G3>=A5,G3<A5+C5),B5/C5,0) -> 1000000 | H5: =IF(AND(H3>=A5,H3<A5+C5),B5/C5,0) -> 1000000 | I5: =IF(AND(I3>=A5,I3<A5+C5),B5/C5,0) -> 1000000 | J5: =IF(AND(J3>=A5,J3<A5+C5),B5/C5,0) -> 1000000 | K5: =IF(AND(K3>=A5,K3<A5+C5),B5/C5,0) -> 1000000 | L5: =IF(AND(L3>=A5,L3<A5+C5),B5/C5,0) -> 1000000 | M5: =IF(AND(M3>=A5,M3<A5+C5),B5/C5,0) -> 1000000 | N5: =IF(AND(N3>=A5,N3<A5+C5),B5/C5,0) -> 1000000 | O5: =IF(AND(O3>=A5,O3<A5+C5),B5/C5,0) -> 0 | P5: =IF(AND(P3>=A5,P3<A5+C5),B5/C5,0) -> 0 | Q5: =IF(AND(Q3>=A5,Q3<A5+C5),B5/C5,0) -> 0 | R5: =IF(AND(R3>=A5,R3<A5+C5),B5/C5,0) -> 0
A6: 2027 | B6: =-Data_Input!T17 -> 10000000 | C6: 10 | D6: =IF(AND(D3>=A6,D3<A6+C6),B6/C6,0) -> 0 | E6: =IF(AND(E3>=A6,E3<A6+C6),B6/C6,0) -> 0 | F6: =IF(AND(F3>=A6,F3<A6+C6),B6/C6,0) -> 1000000 | G6: =IF(AND(G3>=A6,G3<A6+C6),B6/C6,0) -> 1000000 | H6: =IF(AND(H3>=A6,H3<A6+C6),B6/C6,0) -> 1000000 | I6: =IF(AND(I3>=A6,I3<A6+C6),B6/C6,0) -> 1000000 | J6: =IF(AND(J3>=A6,J3<A6+C6),B6/C6,0) -> 1000000 | K6: =IF(AND(K3>=A6,K3<A6+C6),B6/C6,0) -> 1000000 | L6: =IF(AND(L3>=A6,L3<A6+C6),B6/C6,0) -> 1000000 | M6: =IF(AND(M3>=A6,M3<A6+C6),B6/C6,0) -> 1000000 | N6: =IF(AND(N3>=A6,N3<A6+C6),B6/C6,0) -> 1000000 | O6: =IF(AND(O3>=A6,O3<A6+C6),B6/C6,0) -> 1000000 | P6: =IF(AND(P3>=A6,P3<A6+C6),B6/C6,0) -> 0 | Q6: =IF(AND(Q3>=A6,Q3<A6+C6),B6/C6,0) -> 0 | R6: =IF(AND(R3>=A6,R3<A6+C6),B6/C6,0) -> 0
A7: 2028 | B7: =-Data_Input!U17 -> 10000000 | C7: 10 | D7: =IF(AND(D3>=A7,D3<A7+C7),B7/C7,0) -> 0 | E7: =IF(AND(E3>=A7,E3<A7+C7),B7/C7,0) -> 0 | F7: =IF(AND(F3>=A7,F3<A7+C7),B7/C7,0) -> 0 | G7: =IF(AND(G3>=A7,G3<A7+C7),B7/C7,0) -> 1000000 | H7: =IF(AND(H3>=A7,H3<A7+C7),B7/C7,0) -> 1000000 | I7: =IF(AND(I3>=A7,I3<A7+C7),B7/C7,0) -> 1000000 | J7: =IF(AND(J3>=A7,J3<A7+C7),B7/C7,0) -> 1000000 | K7: =IF(AND(K3>=A7,K3<A7+C7),B7/C7,0) -> 1000000 | L7: =IF(AND(L3>=A7,L3<A7+C7),B7/C7,0) -> 1000000 | M7: =IF(AND(M3>=A7,M3<A7+C7),B7/C7,0) -> 1000000 | N7: =IF(AND(N3>=A7,N3<A7+C7),B7/C7,0) -> 1000000 | O7: =IF(AND(O3>=A7,O3<A7+C7),B7/C7,0) -> 1000000 | P7: =IF(AND(P3>=A7,P3<A7+C7),B7/C7,0) -> 1000000 | Q7: =IF(AND(Q3>=A7,Q3<A7+C7),B7/C7,0) -> 0 | R7: =IF(AND(R3>=A7,R3<A7+C7),B7/C7,0) -> 0
A8: 2029 | B8: =-Data_Input!V17 -> 10000000 | C8: 10 | D8: =IF(AND(D3>=A8,D3<A8+C8),B8/C8,0) -> 0 | E8: =IF(AND(E3>=A8,E3<A8+C8),B8/C8,0) -> 0 | F8: =IF(AND(F3>=A8,F3<A8+C8),B8/C8,0) -> 0 | G8: =IF(AND(G3>=A8,G3<A8+C8),B8/C8,0) -> 0 | H8: =IF(AND(H3>=A8,H3<A8+C8),B8/C8,0) -> 1000000 | I8: =IF(AND(I3>=A8,I3<A8+C8),B8/C8,0) -> 1000000 | J8: =IF(AND(J3>=A8,J3<A8+C8),B8/C8,0) -> 1000000 | K8: =IF(AND(K3>=A8,K3<A8+C8),B8/C8,0) -> 1000000 | L8: =IF(AND(L3>=A8,L3<A8+C8),B8/C8,0) -> 1000000 | M8: =IF(AND(M3>=A8,M3<A8+C8),B8/C8,0) -> 1000000 | N8: =IF(AND(N3>=A8,N3<A8+C8),B8/C8,0) -> 1000000 | O8: =IF(AND(O3>=A8,O3<A8+C8),B8/C8,0) -> 1000000 | P8: =IF(AND(P3>=A8,P3<A8+C8),B8/C8,0) -> 1000000 | Q8: =IF(AND(Q3>=A8,Q3<A8+C8),B8/C8,0) -> 1000000 | R8: =IF(AND(R3>=A8,R3<A8+C8),B8/C8,0) -> 0
A9: รวมต่อปี | D9: =SUM(D4:D8) -> 1000000 | E9: =SUM(E4:E8) -> 2000000 | F9: =SUM(F4:F8) -> 3000000 | G9: =SUM(G4:G8) -> 4000000 | H9: =SUM(H4:H8) -> 5000000 | I9: =SUM(I4:I8) -> 5000000 | J9: =SUM(J4:J8) -> 5000000 | K9: =SUM(K4:K8) -> 5000000 | ... R9: =SUM(R4:R8) -> 0
